import { fail } from 'assert';
import { expect } from "chai";
import "mocha";
import { run } from "./helpers.test";

export function assertParseFail(name: string, source: string, line: number, col: number, sourceCode: string ) {
    it(name, async () => {
      try {
        await run(source);
        fail("Expected an exception");
      } catch (err) {
        expect(err.message).to.contain("PARSE ERROR:");
        expect(err.message).to.contain("in line " + line.toString());
        expect(err.message).to.contain("at column " + col.toString());
        expect(err.message).to.contain(sourceCode)
      }
    });
  }
  
  
  export function assertTypeCheckFail(name: string, source: string, line: number, col: number, sourceCode: string ) {
    it(name, async () => {
      try {
        await run(source);
        fail("Expected an exception");
      } catch (err) {
        expect(err.message).to.contain("TYPE ERROR:");
        expect(err.message).to.contain("in line " + line.toString());
        expect(err.message).to.contain("at column " + col.toString());
        expect(err.message).to.contain(sourceCode)
      }
    });
  }
  
  export function assertRunFail(name: string, source: string, line: number, col: number) {
    it(name, async () => {
      try {
        await run(source);
        fail("Expected an exception");
      } catch (err) {
        expect(err.message).to.contain("RUNTIME ERROR:");
        expect(err.message).to.contain("in line " + line.toString());
        expect(err.message).to.contain("at column " + col.toString());
      }
    });
  }
describe("Error Reporting tests", () => {
    //1
    assertParseFail("missing-parenthesis-in-expression", 
    `x: int = 4\nif (x == 6\n\tprint (6)`, 2, 12, "if (x == 6");

    //2
    assertParseFail("invalid-syntax", 
    `x: int = 4\nif (x == 4)::\n\tprint(x)`, 2, 13, 'if (x == 4)::');

    //3
    assertParseFail("missing-type-annotation", 
    `def f(c):
        print(3)
    f(2)
    `, 1, 8, 'def f(c):');

    //4
    assertTypeCheckFail("type-mismatch", 
    `x: int = 1\nx = True`, 2, 8, 'x = True');

    //5
    assertTypeCheckFail("function-call-type-mismatch", 
    `def f(c: int):\n\tprint(c)\nf(2,3)`, 3, 6, 'f(2,3)');

    //6
    assertTypeCheckFail("variable-not-defined-before-accessing", 
    `z = 1`, 1, 5, 'z = 1');

    //7
    assertTypeCheckFail("function-not-defined-before-calling", 
    `def sum(a: int, b: int) -> int:\n\treturn a + b\ndiff(5,7)`, 3,9, 'diff(5,7)');

    //8
    assertTypeCheckFail("return-type-mismatch", 
    `def f(c: int) -> int:\n\treturn True\nf(2)`, 2,12, 'return True');

    //9
    assertRunFail("division-by-zero", 
    `x: int = 100\nx//0`,2,4);

    //10
    assertRunFail("division-by-zero", 
    `x: int = 100\nx%0`,2,3);

 });

 /*
RUNTIME ERROR:

def a() -> int:
    i: int = 0
    j: int = 0
    j = b(i)
    return j

def b(z: int) -> int:
    k: int = 5
    if z == 0:
        c34()
    return k + z

def c34():
    print(1//0)

a()

Output: 
Error: Traceback (most recent call last): 
in line 16: a() 
in line 4: j = b(i) 
in line 10: c34() 

RUNTIME ERROR: division by zero in line 14 at column 14

 */

/*
RUNTIME ERROR: 

def a():
    b()
def b():
    c()
def c():
    d()
def d():
    e()
def e():
    f()
def f():
    g()
def g():
    h()
def h():
    i()
def i():
    j()
def j():
    k()
def k():
    1//0
a()

Output:
Error: Traceback (most recent call last): 
in line 23: a() 
in line 2: b() 
in line 4: c() 
in line 6: d() 
in line 8: e() 
in line 10: f() 
in line 12: g() 
in line 14: h() 
in line 16: i() 
in line 18: j() 
in line 20: k() 

RUNTIME ERROR: division by zero in line 22 at column 8
1//0

*/

/*
RUNTIME ERROR: recursion error

def f():
    f()
f()

Output:
Error: Traceback (most recent call last): 
in line 3: f() 
in line 2: f() 
in line 2: f() 
in line 2: f() 
in line 2: f() 
 [Previous line repeated 995 more times] 
 RUNTIME ERROR: maximum recursion depth exceeded in line 2
f()

*/